Traceback (most recent call last):
  File "main.py", line 5, in <module>
    shutil.rmtree("__pycache__")
  File "/root/anaconda3/lib/python3.6/shutil.py", line 474, in rmtree
    _rmtree_safe_fd(fd, path, onerror)
  File "/root/anaconda3/lib/python3.6/shutil.py", line 432, in _rmtree_safe_fd
    onerror(os.unlink, fullname, sys.exc_info())
  File "/root/anaconda3/lib/python3.6/shutil.py", line 430, in _rmtree_safe_fd
    os.unlink(name, dir_fd=topfd)
FileNotFoundError: [Errno 2] No such file or directory: 'fitness_function.cpython-35.pyc'
Traceback (most recent call last):
  File "main.py", line 5, in <module>
    shutil.rmtree("__pycache__")
  File "/root/anaconda3/lib/python3.6/shutil.py", line 474, in rmtree
    _rmtree_safe_fd(fd, path, onerror)
  File "/root/anaconda3/lib/python3.6/shutil.py", line 432, in _rmtree_safe_fd
    onerror(os.unlink, fullname, sys.exc_info())
  File "/root/anaconda3/lib/python3.6/shutil.py", line 430, in _rmtree_safe_fd
    os.unlink(name, dir_fd=topfd)
FileNotFoundError: [Errno 2] No such file or directory: 'fitness_function.cpython-35.pyc'
Traceback (most recent call last):
  File "main.py", line 5, in <module>
    shutil.rmtree("__pycache__")
  File "/root/anaconda3/lib/python3.6/shutil.py", line 474, in rmtree
    _rmtree_safe_fd(fd, path, onerror)
  File "/root/anaconda3/lib/python3.6/shutil.py", line 432, in _rmtree_safe_fd
    onerror(os.unlink, fullname, sys.exc_info())
  File "/root/anaconda3/lib/python3.6/shutil.py", line 430, in _rmtree_safe_fd
    os.unlink(name, dir_fd=topfd)
FileNotFoundError: [Errno 2] No such file or directory: 'fitness_function.cpython-35.pyc'
Traceback (most recent call last):
  File "/root/mpi_projects/icaro/SleepEEG/Exp/input_output.py", line 10, in verify_create_dir
    os.stat(path)
NotADirectoryError: [Errno 20] Not a directory: 'Teste_1/'

During handling of the above exception, another exception occurred:

Traceback (most recent call last):
  File "main.py", line 349, in <module>
    balance = balance)
  File "main.py", line 25, in main
    verify_create_dir(path)
  File "/root/mpi_projects/icaro/SleepEEG/Exp/input_output.py", line 12, in verify_create_dir
    os.mkdir(path) 	
FileExistsError: [Errno 17] File exists: 'Teste_1/'
Traceback (most recent call last):
  File "main.py", line 5, in <module>
    shutil.rmtree("__pycache__")
  File "/root/anaconda3/lib/python3.6/shutil.py", line 474, in rmtree
    _rmtree_safe_fd(fd, path, onerror)
  File "/root/anaconda3/lib/python3.6/shutil.py", line 432, in _rmtree_safe_fd
    onerror(os.unlink, fullname, sys.exc_info())
  File "/root/anaconda3/lib/python3.6/shutil.py", line 430, in _rmtree_safe_fd
    os.unlink(name, dir_fd=topfd)
FileNotFoundError: [Errno 2] No such file or directory: 'operator_set.cpython-36.pyc'
Traceback (most recent call last):
  File "main.py", line 5, in <module>
    shutil.rmtree("__pycache__")
  File "/root/anaconda3/lib/python3.6/shutil.py", line 474, in rmtree
    _rmtree_safe_fd(fd, path, onerror)
  File "/root/anaconda3/lib/python3.6/shutil.py", line 432, in _rmtree_safe_fd
    onerror(os.unlink, fullname, sys.exc_info())
  File "/root/anaconda3/lib/python3.6/shutil.py", line 430, in _rmtree_safe_fd
    os.unlink(name, dir_fd=topfd)
FileNotFoundError: [Errno 2] No such file or directory: 'fitness_function.cpython-36.pyc'
Traceback (most recent call last):
  File "main.py", line 5, in <module>
    shutil.rmtree("__pycache__")
  File "/root/anaconda3/lib/python3.6/shutil.py", line 474, in rmtree
    _rmtree_safe_fd(fd, path, onerror)
  File "/root/anaconda3/lib/python3.6/shutil.py", line 432, in _rmtree_safe_fd
    onerror(os.unlink, fullname, sys.exc_info())
  File "/root/anaconda3/lib/python3.6/shutil.py", line 430, in _rmtree_safe_fd
    os.unlink(name, dir_fd=topfd)
FileNotFoundError: [Errno 2] No such file or directory: 'input_output.cpython-36.pyc'
Traceback (most recent call last):
  File "/root/mpi_projects/icaro/SleepEEG/Exp/input_output.py", line 10, in verify_create_dir
    os.stat(path)
NotADirectoryError: [Errno 20] Not a directory: 'Teste_1/'

During handling of the above exception, another exception occurred:

Traceback (most recent call last):
  File "main.py", line 349, in <module>
    balance = balance)
  File "main.py", line 25, in main
    verify_create_dir(path)
  File "/root/mpi_projects/icaro/SleepEEG/Exp/input_output.py", line 12, in verify_create_dir
    os.mkdir(path) 	
FileExistsError: [Errno 17] File exists: 'Teste_1/'
Traceback (most recent call last):
  File "main.py", line 5, in <module>
    shutil.rmtree("__pycache__")
  File "/root/anaconda3/lib/python3.6/shutil.py", line 474, in rmtree
    _rmtree_safe_fd(fd, path, onerror)
  File "/root/anaconda3/lib/python3.6/shutil.py", line 432, in _rmtree_safe_fd
    onerror(os.unlink, fullname, sys.exc_info())
  File "/root/anaconda3/lib/python3.6/shutil.py", line 430, in _rmtree_safe_fd
    os.unlink(name, dir_fd=topfd)
FileNotFoundError: [Errno 2] No such file or directory: 'input_output.cpython-36.pyc'
Traceback (most recent call last):
  File "main.py", line 5, in <module>
    shutil.rmtree("__pycache__")
  File "/root/anaconda3/lib/python3.6/shutil.py", line 474, in rmtree
    _rmtree_safe_fd(fd, path, onerror)
  File "/root/anaconda3/lib/python3.6/shutil.py", line 432, in _rmtree_safe_fd
    onerror(os.unlink, fullname, sys.exc_info())
  File "/root/anaconda3/lib/python3.6/shutil.py", line 430, in _rmtree_safe_fd
    os.unlink(name, dir_fd=topfd)
FileNotFoundError: [Errno 2] No such file or directory: 'fitness_function.cpython-36.pyc'
Traceback (most recent call last):
  File "main.py", line 5, in <module>
    shutil.rmtree("__pycache__")
  File "/root/anaconda3/lib/python3.6/shutil.py", line 474, in rmtree
    _rmtree_safe_fd(fd, path, onerror)
  File "/root/anaconda3/lib/python3.6/shutil.py", line 432, in _rmtree_safe_fd
    onerror(os.unlink, fullname, sys.exc_info())
  File "/root/anaconda3/lib/python3.6/shutil.py", line 430, in _rmtree_safe_fd
    os.unlink(name, dir_fd=topfd)
FileNotFoundError: [Errno 2] No such file or directory: 'fitness_function.cpython-36.pyc'
Traceback (most recent call last):
  File "/root/mpi_projects/icaro/SleepEEG/Exp/input_output.py", line 10, in verify_create_dir
    os.stat(path)
NotADirectoryError: [Errno 20] Not a directory: 'Teste_1/'

During handling of the above exception, another exception occurred:

Traceback (most recent call last):
  File "main.py", line 349, in <module>
    balance = balance)
  File "main.py", line 25, in main
    verify_create_dir(path)
  File "/root/mpi_projects/icaro/SleepEEG/Exp/input_output.py", line 12, in verify_create_dir
    os.mkdir(path) 	
FileExistsError: [Errno 17] File exists: 'Teste_1/'
Traceback (most recent call last):
  File "/root/mpi_projects/icaro/SleepEEG/Exp/input_output.py", line 10, in verify_create_dir
    os.stat(path)
NotADirectoryError: [Errno 20] Not a directory: 'Teste_1/'

During handling of the above exception, another exception occurred:

Traceback (most recent call last):
  File "main.py", line 349, in <module>
    balance = balance)
  File "main.py", line 25, in main
    verify_create_dir(path)
  File "/root/mpi_projects/icaro/SleepEEG/Exp/input_output.py", line 12, in verify_create_dir
    os.mkdir(path) 	
FileExistsError: [Errno 17] File exists: 'Teste_1/'
Traceback (most recent call last):
  File "main.py", line 5, in <module>
    shutil.rmtree("__pycache__")
  File "/root/anaconda3/lib/python3.6/shutil.py", line 474, in rmtree
    _rmtree_safe_fd(fd, path, onerror)
  File "/root/anaconda3/lib/python3.6/shutil.py", line 432, in _rmtree_safe_fd
    onerror(os.unlink, fullname, sys.exc_info())
  File "/root/anaconda3/lib/python3.6/shutil.py", line 430, in _rmtree_safe_fd
    os.unlink(name, dir_fd=topfd)
FileNotFoundError: [Errno 2] No such file or directory: 'operator_set.cpython-36.pyc'
Traceback (most recent call last):
  File "main.py", line 5, in <module>
    shutil.rmtree("__pycache__")
  File "/root/anaconda3/lib/python3.6/shutil.py", line 474, in rmtree
    _rmtree_safe_fd(fd, path, onerror)
  File "/root/anaconda3/lib/python3.6/shutil.py", line 432, in _rmtree_safe_fd
    onerror(os.unlink, fullname, sys.exc_info())
  File "/root/anaconda3/lib/python3.6/shutil.py", line 430, in _rmtree_safe_fd
    os.unlink(name, dir_fd=topfd)
FileNotFoundError: [Errno 2] No such file or directory: 'operator_set.cpython-36.pyc'
Traceback (most recent call last):
  File "main.py", line 5, in <module>
    shutil.rmtree("__pycache__")
  File "/root/anaconda3/lib/python3.6/shutil.py", line 474, in rmtree
    _rmtree_safe_fd(fd, path, onerror)
  File "/root/anaconda3/lib/python3.6/shutil.py", line 432, in _rmtree_safe_fd
    onerror(os.unlink, fullname, sys.exc_info())
  File "/root/anaconda3/lib/python3.6/shutil.py", line 430, in _rmtree_safe_fd
    os.unlink(name, dir_fd=topfd)
FileNotFoundError: [Errno 2] No such file or directory: 'input_output.cpython-36.pyc'
Traceback (most recent call last):
  File "main.py", line 5, in <module>
    shutil.rmtree("__pycache__")
  File "/root/anaconda3/lib/python3.6/shutil.py", line 474, in rmtree
    _rmtree_safe_fd(fd, path, onerror)
  File "/root/anaconda3/lib/python3.6/shutil.py", line 432, in _rmtree_safe_fd
    onerror(os.unlink, fullname, sys.exc_info())
  File "/root/anaconda3/lib/python3.6/shutil.py", line 430, in _rmtree_safe_fd
    os.unlink(name, dir_fd=topfd)
FileNotFoundError: [Errno 2] No such file or directory: 'fitness_function.cpython-36.pyc'
Traceback (most recent call last):
  File "main.py", line 5, in <module>
    shutil.rmtree("__pycache__")
  File "/root/anaconda3/lib/python3.6/shutil.py", line 474, in rmtree
    _rmtree_safe_fd(fd, path, onerror)
  File "/root/anaconda3/lib/python3.6/shutil.py", line 432, in _rmtree_safe_fd
    onerror(os.unlink, fullname, sys.exc_info())
  File "/root/anaconda3/lib/python3.6/shutil.py", line 430, in _rmtree_safe_fd
    os.unlink(name, dir_fd=topfd)
FileNotFoundError: [Errno 2] No such file or directory: 'fitness_function.cpython-36.pyc'
Traceback (most recent call last):
  File "main.py", line 5, in <module>
    shutil.rmtree("__pycache__")
  File "/root/anaconda3/lib/python3.6/shutil.py", line 474, in rmtree
    _rmtree_safe_fd(fd, path, onerror)
  File "/root/anaconda3/lib/python3.6/shutil.py", line 432, in _rmtree_safe_fd
    onerror(os.unlink, fullname, sys.exc_info())
  File "/root/anaconda3/lib/python3.6/shutil.py", line 430, in _rmtree_safe_fd
    os.unlink(name, dir_fd=topfd)
FileNotFoundError: [Errno 2] No such file or directory: 'input_output.cpython-36.pyc'
Traceback (most recent call last):
  File "main.py", line 5, in <module>
    shutil.rmtree("__pycache__")
  File "/root/anaconda3/lib/python3.6/shutil.py", line 474, in rmtree
    _rmtree_safe_fd(fd, path, onerror)
  File "/root/anaconda3/lib/python3.6/shutil.py", line 432, in _rmtree_safe_fd
    onerror(os.unlink, fullname, sys.exc_info())
  File "/root/anaconda3/lib/python3.6/shutil.py", line 430, in _rmtree_safe_fd
    os.unlink(name, dir_fd=topfd)
FileNotFoundError: [Errno 2] No such file or directory: 'fitness_function.cpython-36.pyc'
Traceback (most recent call last):
  File "main.py", line 5, in <module>
    shutil.rmtree("__pycache__")
  File "/root/anaconda3/lib/python3.6/shutil.py", line 474, in rmtree
    _rmtree_safe_fd(fd, path, onerror)
  File "/root/anaconda3/lib/python3.6/shutil.py", line 432, in _rmtree_safe_fd
    onerror(os.unlink, fullname, sys.exc_info())
  File "/root/anaconda3/lib/python3.6/shutil.py", line 430, in _rmtree_safe_fd
    os.unlink(name, dir_fd=topfd)
FileNotFoundError: [Errno 2] No such file or directory: 'fitness_function.cpython-36.pyc'
Traceback (most recent call last):
  File "main.py", line 5, in <module>
    shutil.rmtree("__pycache__")
  File "/root/anaconda3/lib/python3.6/shutil.py", line 478, in rmtree
    onerror(os.rmdir, path, sys.exc_info())
  File "/root/anaconda3/lib/python3.6/shutil.py", line 476, in rmtree
    os.rmdir(path)
FileNotFoundError: [Errno 2] No such file or directory: '__pycache__'
Traceback (most recent call last):
  File "main.py", line 5, in <module>
    shutil.rmtree("__pycache__")
  File "/root/anaconda3/lib/python3.6/shutil.py", line 478, in rmtree
    onerror(os.rmdir, path, sys.exc_info())
  File "/root/anaconda3/lib/python3.6/shutil.py", line 476, in rmtree
    os.rmdir(path)
OSError: [Errno 39] Directory not empty: '__pycache__'
Traceback (most recent call last):
  File "main.py", line 5, in <module>
    shutil.rmtree("__pycache__")
  File "/root/anaconda3/lib/python3.6/shutil.py", line 478, in rmtree
    onerror(os.rmdir, path, sys.exc_info())
  File "/root/anaconda3/lib/python3.6/shutil.py", line 476, in rmtree
    os.rmdir(path)
FileNotFoundError: [Errno 2] No such file or directory: '__pycache__'
Traceback (most recent call last):
  File "main.py", line 5, in <module>
    shutil.rmtree("__pycache__")
  File "/root/anaconda3/lib/python3.6/shutil.py", line 474, in rmtree
    _rmtree_safe_fd(fd, path, onerror)
  File "/root/anaconda3/lib/python3.6/shutil.py", line 432, in _rmtree_safe_fd
    onerror(os.unlink, fullname, sys.exc_info())
  File "/root/anaconda3/lib/python3.6/shutil.py", line 430, in _rmtree_safe_fd
    os.unlink(name, dir_fd=topfd)
FileNotFoundError: [Errno 2] No such file or directory: 'input_output.cpython-36.pyc'
Traceback (most recent call last):
  File "main.py", line 295, in <module>
    param2 = int(sys.argv[i+1])
ValueError: invalid literal for int() with base 10: 'relu'
Traceback (most recent call last):
  File "main.py", line 294, in <module>
    opt_vars.append(sys.argv[j+1])
IndexError: list index out of range
/root/anaconda3/lib/python3.6/site-packages/sklearn/metrics/classification.py:1113: UndefinedMetricWarning: Precision and F-score are ill-defined and being set to 0.0 in labels with no predicted samples.
  'precision', 'predicted', average, warn_for)
/root/mpi_projects/icaro/SleepEEG/Exp/operator_set.py:5: RuntimeWarning: divide by zero encountered in double_scalars
  return left / right
/root/anaconda3/lib/python3.6/site-packages/numpy/core/_methods.py:32: RuntimeWarning: invalid value encountered in reduce
  return umr_sum(a, axis, dtype, out, keepdims)
/root/anaconda3/lib/python3.6/site-packages/deap/creator.py:141: RuntimeWarning: A class named 'FitnessMulti' has already been created and it will be overwritten. Consider deleting previous creation of that class or rename it.
  RuntimeWarning)
/root/anaconda3/lib/python3.6/site-packages/deap/creator.py:141: RuntimeWarning: A class named 'Individual' has already been created and it will be overwritten. Consider deleting previous creation of that class or rename it.
  RuntimeWarning)
